<?xml version="1.0" encoding="UTF-8" standalone="yes"?>
<ns2:test-suite xmlns:ns2="urn:model.allure.qatools.yandex.ru" start="1750308547577" stop="1750309336960" version="1.4.0">
    <name>Default suite</name>
    <test-cases>
        <test-case start="1750308573628" stop="1750309227368" status="broken">
            <name>test</name>
            <failure>
                <message>InvocationTargetException: null</message>
                <stack-trace>java.lang.reflect.InvocationTargetException
	at sun.reflect.NativeMethodAccessorImpl.invoke0(Native Method)
	at sun.reflect.NativeMethodAccessorImpl.invoke(Unknown Source)
	at sun.reflect.DelegatingMethodAccessorImpl.invoke(Unknown Source)
	at java.lang.reflect.Method.invoke(Unknown Source)
	at testbase.TestCaseBase.runTest(TestCaseBase.java:243)
	at webportal.OC_changes_Signoff.PRJCBUGEN_T48201.Testcase.test(Testcase.java:48)
	at sun.reflect.NativeMethodAccessorImpl.invoke0(Native Method)
	at sun.reflect.NativeMethodAccessorImpl.invoke(Unknown Source)
	at sun.reflect.DelegatingMethodAccessorImpl.invoke(Unknown Source)
	at java.lang.reflect.Method.invoke(Unknown Source)
	at org.testng.internal.MethodInvocationHelper.invokeMethod(MethodInvocationHelper.java:124)
	at org.testng.internal.MethodInvocationHelper$1.runTestMethod(MethodInvocationHelper.java:230)
	at util.AllureReporterListener.run(AllureReporterListener.java:15)
	at org.testng.internal.MethodInvocationHelper.invokeHookable(MethodInvocationHelper.java:242)
	at org.testng.internal.Invoker.invokeMethod(Invoker.java:579)
	at org.testng.internal.Invoker.invokeTestMethod(Invoker.java:719)
	at org.testng.internal.Invoker.invokeTestMethods(Invoker.java:989)
	at org.testng.internal.TestMethodWorker.invokeTestMethods(TestMethodWorker.java:125)
	at org.testng.internal.TestMethodWorker.run(TestMethodWorker.java:109)
	at org.testng.TestRunner.privateRun(TestRunner.java:648)
	at org.testng.TestRunner.run(TestRunner.java:505)
	at org.testng.SuiteRunner.runTest(SuiteRunner.java:455)
	at org.testng.SuiteRunner.runSequentially(SuiteRunner.java:450)
	at org.testng.SuiteRunner.privateRun(SuiteRunner.java:415)
	at org.testng.SuiteRunner.run(SuiteRunner.java:364)
	at org.testng.SuiteRunnerWorker.runSuite(SuiteRunnerWorker.java:52)
	at org.testng.SuiteRunnerWorker.run(SuiteRunnerWorker.java:84)
	at org.testng.TestNG.runSuitesSequentially(TestNG.java:1208)
	at org.testng.TestNG.runSuitesLocally(TestNG.java:1137)
	at org.testng.TestNG.runSuites(TestNG.java:1049)
	at org.testng.TestNG.run(TestNG.java:1017)
	at org.testng.remote.AbstractRemoteTestNG.run(AbstractRemoteTestNG.java:115)
	at org.testng.remote.RemoteTestNG.initAndRun(RemoteTestNG.java:251)
	at org.testng.remote.RemoteTestNG.main(RemoteTestNG.java:77)
Caused by: java.lang.AssertionError: More device exits expected [true] but found [false]
	at org.testng.Assert.fail(Assert.java:96)
	at org.testng.Assert.failNotEquals(Assert.java:776)
	at org.testng.Assert.assertTrue(Assert.java:44)
	at webportal.OC_changes_Signoff.PRJCBUGEN_T48201.Testcase.step4_aroundBody6(Testcase.java:128)
	at webportal.OC_changes_Signoff.PRJCBUGEN_T48201.Testcase$AjcClosure7.run(Testcase.java:1)
	at org.aspectj.runtime.reflect.JoinPointImpl.proceed(JoinPointImpl.java:149)
	at io.qameta.allure.aspects.StepsAspects.step(StepsAspects.java:51)
	at webportal.OC_changes_Signoff.PRJCBUGEN_T48201.Testcase.step4(Testcase.java:112)
	... 34 more
</stack-trace>
            </failure>
            <steps/>
            <attachments/>
            <labels/>
        </test-case>
    </test-cases>
    <labels>
        <label name="framework" value="TestNG"/>
        <label name="feature" value="Default test"/>
        <label name="language" value="JAVA"/>
    </labels>
</ns2:test-suite>
